## 8.1 예외처리

### 프로그램 오류

프로그램 오류는 발생시점에 따라 '컴파일 에러(compile-time error)'와 '런타임 에러(runtime error)'로 나눌 수 있다.
글자 그대로 '컴파일 에러'는 컴파일 할 때 발생하는 에러이고 프로그램의 실행도중에 발생하는 에러를 '런타임 에러'라고 한다.
이 외에도 '논리적 에러(logical error)'가 있는데, 컴파일도 잘되고 실행도 잘되지만 의도한 것과 다르게 동작하는 것을 말한다.<br>
<br>
소스코드를 컴파일하면 컴파일러가 소스코드(&#42;.java)에 대해 오타나 잘못된 구문, 자료형 체크 등의 기본적인 검사를 수행하여 오류가 있는지를 알려준다.
컴파일러가 알려 준 에러들을 모두 수정해서 컴파일을 성공적으로 마치고 나면, 클래스 파일(&#42;.class)이 생성되고, 생성된 클래스 파일을 실행할 수 있게
되는 것이다.<br>
<br>
컴파일을 성공적으로 마쳐도 에러가 발생할 수 있다. 컴파일러가 소스코드의 기본적인 사항은 컴파일 시에 모두 걸러주지만, 실행도중 발생할 수 있는
잠재적인 오류까지 검사할 수 없기 때문이다. 예를 들면 프로그램이 실행 중 동작을 멈춘 상태로 오랜시간 지속되거나, 갑자기 프로그램이 실행을
멈추고 종료되는 경우 등이 이에 해당한다.<br>
<br>
***런타임 에러를 방지하기 위해서는 프로그램의 실행도중 발생할 수 있는 모든 경우의 수를 고려하여 이에 대한 대비를 하는 것이 필요하다.***<br>
자바에서는 실행시(runtime) 발생할 수 있는 프로그램 오류를 '에러(error)'와 '예외(exception)', 두 가지로 구분하였다. 에러는 메모리 부족(OutOfMemoryError)이나
스택오버플로우(StackOverflowError)와 같이 일단 발생하면 복구할 수 없는 심각한 오류이고, 예외는 발생하더라도 수습될 수 있는 비교적 덜 심각한 것이다.<br>
<br>
에러가 발생하면, 프로그램의 비정상적인 종료를 막을 길이 없지만, 예외는 발생하더라도 프로그래머가 이에 대한 적절한 코드를 미리 작성해 놓음으로써 프로그램의 비정상적인 종료를
막을 수 있다.

    에러(error)       프로그램 코드에 의해서 수습될 수 없는 심각한 오류
    예외(exception)   프로그램 코드에 의해서 수습될 수 있는 다소 미약한 오류

### 예외 클래스의 계층구조

자바에서는 실행 시 발생할 수 있는 오류(Exception과 Error)를 클래스로 정의하였다. 앞서 배운 것처럼 모든 클래스의 조상은 Object클래스이므로
Exception과 Error클래스 역시 Object클래스의 자손들이다.

<figure>
    <img src="https://velog.velcdn.com/images/mingseok/post/55d9e691-cea8-4add-8859-327a9c1e4521/image.png">
</figure>

모든 예외의 최고 조상은 Exception클래스이며, 상속계층도를 Exception클래스부터 도식화하면 다음과 같다.

<figure>
    <img src="https://images.velog.io/images/kookiencream/post/44938894-584d-4ee5-9733-4903e956d49f/java_image_121.png">
</figure>

위 그림에서 볼 수 있듯이 예외 클래스들은 다음과 같이 두 그룹으로 나눠질 수 있다.

1. Exception클래스와 그 자손들(그림의 윗부분, RuntimeException과 자손들 제외)
2. RuntimeException클래스와 그 자손들(그림의 아랫부분)

앞으로 RuntimeException클래스와 그 자손 클래스들을 'RuntimeException클래스들'이라 하고, RuntimeException클래스들을 제외한 나머지 클래스들을
'Exception클래스들'이라 하겠다.<br>
<br>
***RuntimeException***클래스들은 주로 프로그래머의 실수에 의해서 발생될 수 있는 예외들로 자바의 프로그래밍 요소들과 관계가 깊다. 예를 들면, 배열의 범위를
벗어난다던가(ArrayIndexOutOfBoundsException), 값이 null인 참조변수의 멤버를 호출하려 했다던가(NullPointerException), 클래스간의
형변환을 잘못했다던가(ClassCastException), 정수를 0으로 나누려고(ArithmeticException)하는 경우에 발생한다.<br>
<br>
***Exception***클래스들은 주로 외부의 영향으로 발생할 수 있는 것들로서, 프로그램의 사용자들의 동작에 의해서 발생하는 경우가 많다. 예를 들면, 존재하지
않는 파일의 이름을 입력했다던가(FileNotFoundException), 실수로 클래스의 이름을 잘못 적었다던가(ClassNotFoundException), 또는 입력한 데이터 형식이
잘못된(DataFormatException)경우에 발생한다.

1. Exception클래스들 : 사용자의 실수와 같은 외적인 요인에 의해 발생하는 예외
2. RuntimeException클래스들 : 프로그래머의 실수로 발생하는 예외

### 예외처리하기 - try - catch문

프로그램의 실행도중에 발생하는 에러는 어쩔 수 없지만, 예외는 프로그래머가 이에 대한 처리를 미리 해주어야 한다. 예외처리란, 프로그램 실행시 발생할 수 있는
예기치 못한 예외의 발생에 대비한 코드를 작성하는 것이며, 예외처리의 목적은 예외의 발생으로 인한 실행 중인 프로그램의 갑작스런 비정상 종료를 막고,
정상적인 실행상태를 유지할 수 있도록 하는 것이다.<br>
예외를 처리하기 위해서는 try-catch문을 사용하며, 그 구조는 다음과 같다.

```java
try{
        // 예외가 발생할 가능성이 있는 문장들을 넣는다.    
        }catch(Exception1 e1){
        // Exception1이 발생했을 경우, 이를 처리하기 위한 문장을 적는다.    
        }catch(Exception2 e2){
        // Exception2이 발생했을 경우, 이를 처리하기 위한 문장을 적는다.    
        }catch(Exception3 e3){
        // Exception3이 발생했을 경우, 이를 처리하기 위한 문장을 적는다.    
        }
```

하나의 try블럭 다음에는 여러 종류의 예외를 처리할 수 있도록 하나 이상의 catch블럭이 올 수 있으며, 이 중 ***발생한 예외의 종류와 일치하는 단 한개의
catch블럭만 수행된다.*** 발생한 예외의 종류와 일치하는 catch블럭이 없으면 예외는 처리되지 않는다.

```java
class ExceptionEx1 {
    public static void main(String[] args) {
        try {
            try {
            } catch (Exception e) {
            }
        } catch (Exception e) {
            try {
            } catch (Exception e) {
            }   // 에러. 변수 e가 중복선언되었다.
        }   // try-catch의 끝

        try {

        } catch (Exception e) {

        } // try-catch의 끝
    }   // main메서드의 끝
}
```

위의 예제는 아무일도 하지 않는다. 단순히 try-catch문의 사용예를 보여주기 위해서 작성한 코드이다. 이처럼 하나의 메서드 내에 여러개의 try-catch문이
사용될 수 있으며, try블럭 또는 catch블럭에 또 다른 try-catch문이 포함될 수 있다. catch블럭 내의 코드에서도 예외가 발생할 수 있기 때문이다. catch블럭의 괄호 내에 선언된 변수는
catch블럭 내에서만 유효하기 때문에, 위의 모든 catch블럭에 참조변수 'e'하나 만을 사용해도 된다.<br>
그러나 catch블럭 내에 또 하나의 try-catch문이 포함된 경우, 같은 이름의 참조변수를 사용해서는 안된다. 각 catch블럭에 선언된 두 참조변수의 영역이 서로 겹치므로 다른 이름을 사용해야만
서로 구별되기 때문이다.<br>
따라서 위의 예제에서 catch블럭 내의 try-catch문에 선언되어 있는 참조변수의 이름을 'e'가 아닌 다른 것으로 바꿔야 한다.

```java
class ExceptionEx2 {
    public static void main(String[] args) {
        int number = 100;
        int result = 0;

        for (int i = 0; i < 10; i++) {
            result = number / (int) (Math.random() * 10);
            System.out.println(result);
        }
    }
    // Exception in thread "main" java.lang.ArithmeticException: / by zero
}
```

random()을 사용했기 때문에 매번 실행할 때마다 결과가 다르겠지만, 대부분의 경우 10번이 출력되기 이전에 예외가 발생하여 프로그램이 비정상적으로 종료될 것이다.
ArithmeticException은 산술연산과정에서 오류가 있을 때 발생한다. 정수는 0으로 나누는 것이 금지되어있기 때문에 발생했다.

```java
class ExceptionEx2 {
    public static void main(String[] args) {
        int number = 100;
        int result = 0;

        for (int i = 0; i < 10; i++) {
            try {
                result = number / (int) (Math.random() * 10);
                System.out.println(result);
            } catch (ArithmeticException e) {
                System.out.println("0");    // ArithmeticException이 발생하면 실행되는 코드
            }
        }
    }
//            16
//            14
//            33
//            20
//            20
//            0     <--- ArithmeticException이 발생해서 0이 출력되었다.
//            33
//            16
//            14
//            33
}
```
위의 예제는 단순히 try-catch문을 추가한 것이다. ArithmeticException이 발생했을 경우, 0을 화면에 출력하도록 했다. 만일 예외처리를
하지 않았다면 5번째줄까지만 출력되고 예외가 발생해서 프로그램이 비정상적으로 종료되었을 것이다.

### try-catch문에서의 흐름

try-catch문에서, 예외가 발생한 경우와 발생하지 않았을 때의 흐름(문장의 실행순서)이 달라지는데, 아래에 이 두 가지 경우에 따른 문장 실행순서를
정리하였다.

        ● try블럭 내에서 예외가 발생한 경우,
        1. 발생한 예외와 일치하는 catch블럭이 있는지 확인한다.
        2. 일치하는 catch블럭을 찾게되면, 그 catch블럭 내의 문장들을 수행하고 전체 try-catch문을 빠져나가서 그 다음 문장을 계속해서 수행한다.
           만일 일치하는 catch블럭을 찾지 못하면, 예외는 처리되지 못한다.
        
        ● try블럭 내에서 예외가 발생하지 않은 경우,
        1. catch블럭을 거치지 않고 전체 try-catch문을 빠져나가서 수행을 계속한다.

```java
class ExceptionEx4 {
    public static void main(String[] args) {
        System.out.println(1);
        System.out.println(2);
        
        try {
            System.out.println(3);
            System.out.println(4);
        } catch (Exception e) {
            System.out.println(5);  // 실행되지 않는다
        }
        System.out.println(6);
    }
//    1
//    2
//    3
//    4
//    6
}
```
위의 예제에서는 예외가 발생하지 않아 catch블럭의 문장이 실행되지 않았다. 다음의 예제는 위의 예제를 변경해서, try블럭에서 예외가 발생하도록 하였다.

```java
// 예제 8-5
class ExceptionEx5 {
    public static void main(String[] args) {
        System.out.println(1);
        System.out.println(2);
        try {
            System.out.println(3);
            System.out.println(0/0);    // ArithmeticException. 실행되지 않는다
            System.out.println(4);
        } catch(ArithmeticException ae) {
            System.out.println(5);
        }
        System.out.println(6);
    }
//    1
//    2
//    3
//    5
//    6
}
```
try블럭에서 예외가 발생하면, 예외가 발생한 위치 이후에 있는 try블럭의 문장들은 수행되지 않으므로, try블럭에 포함시킬 코드의 범위를 잘 선택해야 한다.

### 예외의 발생과 catch블럭
catch블럭은 괄호()와 블럭{} 두 부분으로 나눠져 있는데, 괄호()내에는 처리하고자 하는 예외와 같은 타입의 참조변수 하나를 선언해야 한다.<br>
***예외가 발생하면, 발생한 예외에 해당하는 클래스의 인스턴스가 만들어진다.***<br>

위의 예제8-5에서는 ArithmeticException이 발생했으므로 ArithmeticException인스턴스가 생성된다. 예외가 발생한 문장이 try블럭에 포함되어 있다면,
이 예외를 처리할 수 있는 catch블럭이 있는지 찾게 된다.<br>
<br>
첫번째 catch블럭부터 차례로 내려가면서 catch블럭의 괄호()내에 선언된 참조변수의 종류와 생성된 예외클래스의 인스턴스에 instanceof연산자를 이용해서 검사하게 되는데,
검사결과가 true인 catch블럭을 만날 때까지 검사는 계속된다.<br>
검사결과가 true인 catch블럭을 찾게 되면 블럭에 있는 문장들을 모두 수행한 후에 try-catch문을 빠져나가고 예외는 처리되지만, 검사결과가 true인 catch블럭이 하나도
없으면 예외는 처리되지 않는다.<br>
<br>
모든 예외 클래스는 Exception클래스의 자손이므로, catch블럭의 괄호()에 Exception클래스 타입의 참조변수를 선언해 놓으면 어떤 종류의
예외가 발생하더라도 이 catch블럭에 의해서 처리된다.

```java
class ExceptionEx7 {
    public static void main(String[] args) {
        System.out.println(1);
        System.out.println(2);
        try {
            System.out.println(3);
            System.out.println(0/0);
            System.out.println(4);
        } catch(ArithmeticException ae) {
            if(ae instanceof ArithmeticException)
                System.out.println("ArithmeticException");
            System.out.println("ArithmeticException");
        } catch(Exception e) {  // ArithmeticException을 제외한 모든 예외가 처리된다.
            System.out.println("Exception");
        } // try-catch의 끝
        System.out.println(6);
    }   // main메서드의 끝
}
```
try블럭에서 ArithmeticException이 발생하였으므로 catch블럭을 하나씩 차례로 검사하게 되는데, 첫번째 검사에서 일치하는 catch블럭을 찾았기 때문에
두번째 catch블럭은 검사하지 않게 된다. 만일 try블럭 내에서 ArithmeticException이 아닌 다른 종류의 예외가 발생한 경우에는 두번째 catch블럭인 Exception클래스 타입의
참조변수를 선언한 곳에서 처리되었을 것이다.<br>
<br>
***이처럼, try-catch분의 마지막에 Exception클래스 타입의 참조변수를 선언한 catch블럭을 사용하면, 어떤 종류의 예외가 발생하더라도 이 catch블럭에 의해 처리되도록 할 수 있다.***

### printStackTrace()와 getMessage()
예외가 발생했을 때 생성되는 예외클래스의 인스턴스에는 발생한 예외에 대한 정보가 담겨 있으며, getMessage()와 printStackTrace()를 통해서 이 정보들을
얻을 수 있다. catch블럭의 괄호()에 선언된 참조변수를 통해 이 인스턴스에 접근할 수 있다. 이 참조변수는 선언된 catch블럭내에서만 사용가능하며, 자주 사용되는 메서드는
다음과 같다.

        printStackTrace() 예외발생 당시의 호출스택(Call Stack)에 있었던 메서드의 정보와 예외메시지를 화면에 출력한다.
        getMessage()      발생한 예외클래스의 인스턴스에 저장된 메시지를 얻을 수 있다.

```java
class ExceptionEx8 {
    public static void main(String[] args) {
        System.out.println(1);
        System.out.println(2);
        try {
            System.out.println(3);
            System.out.println(0/0);    // 예외발생!!!
            System.out.println(4);
        } catch(ArithmeticException ae) {
            ae.printStackTrace();   // 참조변수 ae를 통해, 생성된 ArithmeticException인스턴스에 접근할 수 있다.
            System.out.println("예외메시지 : " + ae.getMessage());
        }
        System.out.println(6);
    }
}
//        1
//        2
//        3
//        예외메시지 : / by zero
//        6
//        java.lang.ArithmeticException: / by zero
//        at test.main(test.java:7)
```
위 예제의 결과는 예외가 발생해서 비정상적으로 종료되었을 때의 결과와 비슷하지만 예외는 try-catch문에 의해 처리되었으며 프로그램은 정상적으로 종료되었다.
<br>
그 대신 ArithmeticException인스턴스의 printStackTrace()를 사용해서, 호출스택(call stack)에 대한 정보와 예외 메시지를 출력하였다. 이처럼 try-catch문으로
예외처리를 하여 예외가 발생해도 비정상적으로 종료하지 않도록 해주는 동시에, printStackTrace() 또는 getMessage()와 같은 메서드를 통해서 예외의 발생원인을
알 수 있다.

### 예외 발생시키기

키워드 throw를 사용해서 프로그래머가 고의로 예외를 발생시킬 수 있으며, 방법은 아래의 순서를 따르면 된다.